terminate called after throwing an instance of 'std::runtime_error'
  what():  Objective already completed!
Aborted
